Workbook

Sheet README
A1: MODEL VILLAGE — MASTER DATA
A2: Built from: MV-Comittees-26-27.xlsx | Program: Model Village Program 2026-2027 | Donor: Sopar
A4: SHEETS IN THIS WORKBOOK
A5: 1. DAs — one row per Development Associate (field staff)
A6: 2. Villages — one row per village, rolls up from Committees
A7: 3. Committees — one row per village-committee (351 total), rolls up from Committee_Members
A8: 4. Committee_Members — one row per individual committee member (2,433 total) — this is the source of truth; all totals elsewhere are formulas pointing back here
A9: 5. Action_Plans — one row per Committee, pre-populated and ready for you to fill in Type / Frequency / Assigned Date (yellow cells). This doubles as the import template.
A10: 6. Attendance_Entries — schema + 1 example row for the DA Attendance app module
A11: 7. Specials_Entries — schema + 1 example row for the DA Specials app module
A13: HOW TOTALS WORK
A14: Committee_Members is the only sheet with hand-entered/raw data. Every Male/Female/Member count in Committees, Villages, and DAs is a COUNTIFS/SUMIFS formula reading off Committee_Members and Committees — edit a member's Gender there and the totals recalculate everywhere.
... A43: - Confirm: should PCs see each other's data directly, or only PM consolidates the cross-PC view? Currently modeled as the latter.

Sheet DAs
A1: DA_ID | B1: DA_Name | C1: Cluster | D1: Email | E1: Mobile | F1: Villages_Assigned | G1: Total_Committee_Members | H1: PC_ID
A2: D01 | B2: D.Ramesh | C2: CSRB | F2: =COUNTIF(Villages!F:F,A2) | G2: =SUMIFS(Villages!K:K,Villages!F:F,A2) | H2: =IFERROR(INDEX(PC_DA_Map!$B:$B,MATCH(A2,PC_DA_Map!$C:$C,0)),"")
A3: D02 | B3: K.Krishna | C3: CSRB | F3: =COUNTIF(Villages!F:F,A3) | G3: =SUMIFS(Villages!K:K,Villages!F:F,A3) | H3: =IFERROR(INDEX(PC_DA_Map!$B:$B,MATCH(A3,PC_DA_Map!$C:$C,0)),"")
A4: D03 | B4: K.Vinaykumar | C4: PDTC | F4: =COUNTIF(Villages!F:F,A4) | G4: =SUMIFS(Villages!K:K,Villages!F:F,A4) | H4: =IFERROR(INDEX(PC_DA_Map!$B:$B,MATCH(A4,PC_DA_Map!$C:$C,0)),"")
A5: D04 | B5: M.Venkatesh | C5: CSRB | F5: =COUNTIF(Villages!F:F,A5) | G5: =SUMIFS(Villages!K:K,Villages!F:F,A5) | H5: =IFERROR(INDEX(PC_DA_Map!$B:$B,MATCH(A5,PC_DA_Map!$C:$C,0)),"")
A6: D05 | B6: P.Shankar | C6: PDTC | F6: =COUNTIF(Villages!F:F,A6) | G6: =SUMIFS(Villages!K:K,Villages!F:F,A6) | H6: =IFERROR(INDEX(PC_DA_Map!$B:$B,MATCH(A6,PC_DA_Map!$C:$C,0)),"")
A7: D06 | B7: R.Vinay | C7: PDTC | F7: =COUNTIF(Villages!F:F,A7) | G7: =SUMIFS(Villages!K:K,Villages!F:F,A7) | H7: =IFERROR(INDEX(PC_DA_Map!$B:$B,MATCH(A7,PC_DA_Map!$C:$C,0)),"")
A8: D07 | B8: T.Ramesh | C8: CSRB | F8: =COUNTIF(Villages!F:F,A8) | G8: =SUMIFS(Villages!K:K,Villages!F:F,A8) | H8: =IFERROR(INDEX(PC_DA_Map!$B:$B,MATCH(A8,PC_DA_Map!$C:$C,0)),"")
A9: D08 | B9: V.Ramesh | C9: CSRB | F9: =COUNTIF(Villages!F:F,A9) | G9: =SUMIFS(Villages!K:K,Villages!F:F,A9) | H9: =IFERROR(INDEX(PC_DA_Map!$B:$B,MATCH(A9,PC_DA_Map!$C:$C,0)),"")
A10: D09 | B10: Y.Rakesh | C10: PDTC | F10: =COUNTIF(Villages!F:F,A10) | G10: =SUMIFS(Villages!K:K,Villages!F:F,A10) | H10: =IFERROR(INDEX(PC_DA_Map!$B:$B,MATCH(A10,PC_DA_Map!$C:$C,0)),"")

Sheet Villages
A1: Village_ID | B1: Village | C1: Mandal | D1: District | E1: Cluster | F1: DA_ID | G1: DA_Name | H1: Committee_Count | I1: Total_Male | J1: Total_Female | K1: Total_Members
A2: V01 | B2: Thigul narsapur | C2: Jagdevpur | D2: Siddipet | E2: CSRB | F2: D07 | G2: T.Ramesh | H2: =COUNTIF(Committees!B:B,A2) | I2: =SUMIFS(Committees!E:E,Committees!B:B,A2) | J2: =SUMIFS(Committees!F:F,Committees!B:B,A2) | K2: =I2+J2
A3: V02 | B3: B.G.Venkatapur | C3: Jagdevpur | D3: Siddipet | E3: CSRB | F3: D07 | G3: T.Ramesh | H3: =COUNTIF(Committees!B:B,A3) | I3: =SUMIFS(Committees!E:E,Committees!B:B,A3) | J3: =SUMIFS(Committees!F:F,Committees!B:B,A3) | K3: =I3+J3
A4: V03 | B4: Thimmapur | C4: Jagdevpur | D4: Siddipet | E4: CSRB | F4: D07 | G4: T.Ramesh | H4: =COUNTIF(Committees!B:B,A4) | I4: =SUMIFS(Committees!E:E,Committees!B:B,A4) | J4: =SUMIFS(Committees!F:F,Committees!B:B,A4) | K4: =I4+J4
A5: V04 | B5: Palugugadda | C5: Jagdevpur | D5: Siddipet | E5: CSRB | F5: D07 | G5: T.Ramesh | H5: =COUNTIF(Committees!B:B,A5) | I5: =SUMIFS(Committees!E:E,Committees!B:B,A5) | J5: =SUMIFS(Committees!F:F,Committees!B:B,A5) | K5: =I5+J5
A6: V05 | B6: Wattipally | C6: Jagdevpur | D6: Siddipet | E6: CSRB | F6: D07 | G6: T.Ramesh | H6: =COUNTIF(Committees!B:B,A6) | I6: =SUMIFS(Committees!E:E,Committees!B:B,A6) | J6: =SUMIFS(Committees!F:F,Committees!B:B,A6) | K6: =I6+J6
A7: V06 | B7: Angadikistapur | C7: Markook | D7: Siddipet | E7: CSRB | F7: D01 | G7: D.Ramesh | H7: =COUNTIF(Committees!B:B,A7) | I7: =SUMIFS(Committees!E:E,Committees!B:B,A7) | J7: =SUMIFS(Committees!F:F,Committees!B:B,A7) | K7: =I7+J7
A8: V07 | B8: Ganeshpalli | C8: Markook | D8: Siddipet | E8: CSRB | F8: D01 | G8: D.Ramesh | H8: =COUNTIF(Committees!B:B,A8) | I8: =SUMIFS(Committees!E:E,Committees!B:B,A8) | J8: =SUMIFS(Committees!F:F,Committees!B:B,A8) | K8: =I8+J8
A9: V08 | B9: Kondapur | C9: Jagdevpur | D9: Siddipet | E9: CSRB | F9: D01 | G9: D.Ramesh | H9: =COUNTIF(Committees!B:B,A9) | I9: =SUMIFS(Committees!E:E,Committees!B:B,A9) | J9: =SUMIFS(Committees!F:F,Committees!B:B,A9) | K9: =I9+J9
A10: V09 | B10: Chebarthy | C10: Markook | D10: Siddipet | E10: CSRB | F10: D01 | G10: D.Ramesh | H10: =COUNTIF(Committees!B:B,A10) | I10: =SUMIFS(Committees!E:E,Committees!B:B,A10) | J10: =SUMIFS(Committees!F:F,Committees!B:B,A10) | K10: =I10+J10
A11: V10 | B11: Kothapet | C11: Jagdevpur | D11: Siddipet | E11: CSRB | F11: D01 | G11: D.Ramesh | H11: =COUNTIF(Committees!B:B,A11) | I11: =SUMIFS(Committees!E:E,Committees!B:B,A11) | J11: =SUMIFS(Committees!F:F,Committees!B:B,A11) | K11: =I11+J11
A12: V11 | B12: PT Venkatapur | C12: Kukunoorpalli | D12: Siddipet | E12: CSRB | F12: D04 | G12: M.Venkatesh | H12: =COUNTIF(Committees!B:B,A12) | I12: =SUMIFS(Committees!E:E,Committees!B:B,A12) | J12: =SUMIFS(Committees!F:F,Committees!B:B,A12) | K12: =I12+J12
A13: V12 | B13: Rayavaram | C13: Kukunoorpalli | D13: Siddipet | E13: CSRB | F13: D04 | G13: M.Venkatesh | H13: =COUNTIF(Committees!B:B,A13) | I13: =SUMIFS(Committees!E:E,Committees!B:B,A13) | J13: =SUMIFS(Committees!F:F,Committees!B:B,A13) | K13: =I13+J13
... A43: V42 | B43: Ontimamidipalli | C43: Inavolu | D43: Hanmakonda | E43: PDTC | F43: D09 | G43: Y.Rakesh | H43: =COUNTIF(Committees!B:B,A43) | I43: =SUMIFS(Committees!E:E,Committees!B:B,A43) | J43: =SUMIFS(Committees!F:F,Committees!B:B,A43) | K43: =I43+J43

Sheet Committees
A1: Committee_ID | B1: Village_ID | C1: Village | D1: Committee_Name | E1: Total_Male | F1: Total_Female | G1: Total_Members
A2: C0001 | B2: V01 | C2: Thigul narsapur | D2: VDC | E2: =COUNTIFS(Committee_Members!B:B,A2,Committee_Members!G:G,"Male") | F2: =COUNTIFS(Committee_Members!B:B,A2,Committee_Members!G:G,"Female") | G2: =COUNTIF(Committee_Members!B:B,A2)
A3: C0002 | B3: V01 | C3: Thigul narsapur | D3: Environment | E3: =COUNTIFS(Committee_Members!B:B,A3,Committee_Members!G:G,"Male") | F3: =COUNTIFS(Committee_Members!B:B,A3,Committee_Members!G:G,"Female") | G3: =COUNTIF(Committee_Members!B:B,A3)
A4: C0003 | B4: V01 | C4: Thigul narsapur | D4: Education | E4: =COUNTIFS(Committee_Members!B:B,A4,Committee_Members!G:G,"Male") | F4: =COUNTIFS(Committee_Members!B:B,A4,Committee_Members!G:G,"Female") | G4: =COUNTIF(Committee_Members!B:B,A4)
A5: C0004 | B5: V01 | C5: Thigul narsapur | D5: Technical & Youth | E5: =COUNTIFS(Committee_Members!B:B,A5,Committee_Members!G:G,"Male") | F5: =COUNTIFS(Committee_Members!B:B,A5,Committee_Members!G:G,"Female") | G5: =COUNTIF(Committee_Members!B:B,A5)
A6: C0005 | B6: V01 | C6: Thigul narsapur | D6: Water | E6: =COUNTIFS(Committee_Members!B:B,A6,Committee_Members!G:G,"Male") | F6: =COUNTIFS(Committee_Members!B:B,A6,Committee_Members!G:G,"Female") | G6: =COUNTIF(Committee_Members!B:B,A6)
A7: C0006 | B7: V01 | C7: Thigul narsapur | D7: Health | E7: =COUNTIFS(Committee_Members!B:B,A7,Committee_Members!G:G,"Male") | F7: =COUNTIFS(Committee_Members!B:B,A7,Committee_Members!G:G,"Female") | G7: =COUNTIF(Committee_Members!B:B,A7)
A8: C0007 | B8: V01 | C8: Thigul narsapur | D8: Farmer | E8: =COUNTIFS(Committee_Members!B:B,A8,Committee_Members!G:G,"Male") | F8: =COUNTIFS(Committee_Members!B:B,A8,Committee_Members!G:G,"Female") | G8: =COUNTIF(Committee_Members!B:B,A8)
A9: C0008 | B9: V02 | C9: B.G.Venkatapur | D9: Environment | E9: =COUNTIFS(Committee_Members!B:B,A9,Committee_Members!G:G,"Male") | F9: =COUNTIFS(Committee_Members!B:B,A9,Committee_Members!G:G,"Female") | G9: =COUNTIF(Committee_Members!B:B,A9)
A10: C0009 | B10: V02 | C10: B.G.Venkatapur | D10: Farmer | E10: =COUNTIFS(Committee_Members!B:B,A10,Committee_Members!G:G,"Male") | F10: =COUNTIFS(Committee_Members!B:B,A10,Committee_Members!G:G,"Female") | G10: =COUNTIF(Committee_Members!B:B,A10)
A11: C0010 | B11: V02 | C11: B.G.Venkatapur | D11: Gender | E11: =COUNTIFS(Committee_Members!B:B,A11,Committee_Members!G:G,"Male") | F11: =COUNTIFS(Committee_Members!B:B,A11,Committee_Members!G:G,"Female") | G11: =COUNTIF(Committee_Members!B:B,A11)
A12: C0011 | B12: V02 | C12: B.G.Venkatapur | D12: Health | E12: =COUNTIFS(Committee_Members!B:B,A12,Committee_Members!G:G,"Male") | F12: =COUNTIFS(Committee_Members!B:B,A12,Committee_Members!G:G,"Female") | G12: =COUNTIF(Committee_Members!B:B,A12)
A13: C0012 | B13: V02 | C13: B.G.Venkatapur | D13: Problem Solving | E13: =COUNTIFS(Committee_Members!B:B,A13,Committee_Members!G:G,"Male") | F13: =COUNTIFS(Committee_Members!B:B,A13,Committee_Members!G:G,"Female") | G13: =COUNTIF(Committee_Members!B:B,A13)
... A352: C0351 | B352: V42 | C352: Ontimamidipalli | D352: Gender | E352: =COUNTIFS(Committee_Members!B:B,A352,Committee_Members!G:G,"Male") | F352: =COUNTIFS(Committee_Members!B:B,A352,Committee_Members!G:G,"Female") | G352: =COUNTIF(Committee_Members!B:B,A352)

Sheet Committee_Members
A1: Member_ID | B1: Committee_ID | C1: Village_ID | D1: Village | E1: Committee_Name | F1: Name | G1: Gender | H1: Designation | I1: Designation_Raw | J1: Mobile | K1: Mobile_Valid
A2: M00001 | B2: C0001 | C2: V01 | D2: Thigul narsapur | E2: VDC | F2: G.Praveen | G2: Male | H2: President | I2: President | J2: 8187815102 | K2: =IF(TRIM(J2&"")="","Blank",IFERROR(IF(AND(LEN(TRIM(J2))=10,VALUE(TRIM(J2))>0),"Valid","Invalid"),"Invalid"))
A3: M00002 | B3: C0001 | C3: V01 | D3: Thigul narsapur | E3: VDC | F3: M.Laxminarsimhareddy | G3: Male | H3: Vice President | I3: Wise president | J3: 9652472270 | K3: =IF(TRIM(J3&"")="","Blank",IFERROR(IF(AND(LEN(TRIM(J3))=10,VALUE(TRIM(J3))>0),"Valid","Invalid"),"Invalid"))
A4: M00003 | B4: C0001 | C4: V01 | D4: Thigul narsapur | E4: VDC | F4: Kancharla Raju | G4: Male | H4: Secretary | I4: Secretory | J4: 9652532096 | K4: =IF(TRIM(J4&"")="","Blank",IFERROR(IF(AND(LEN(TRIM(J4))=10,VALUE(TRIM(J4))>0),"Valid","Invalid"),"Invalid"))
A5: M00004 | B5: C0001 | C5: V01 | D5: Thigul narsapur | E5: VDC | F5: M.Kavitha | G5: Female | H5: Member | I5: Member | J5: 7893213229 | K5: =IF(TRIM(J5&"")="","Blank",IFERROR(IF(AND(LEN(TRIM(J5))=10,VALUE(TRIM(J5))>0),"Valid","Invalid"),"Invalid"))
A6: M00005 | B6: C0001 | C6: V01 | D6: Thigul narsapur | E6: VDC | F6: U.Narsimhulu | G6: Male | H6: President | I6: President | J6: 9676218478 | K6: =IF(TRIM(J6&"")="","Blank",IFERROR(IF(AND(LEN(TRIM(J6))=10,VALUE(TRIM(J6))>0),"Valid","Invalid"),"Invalid"))
A7: M00006 | B7: C0001 | C7: V01 | D7: Thigul narsapur | E7: VDC | F7: M.Manasa | G7: Female | H7: Member | I7: Member | J7: 7288036164 | K7: =IF(TRIM(J7&"")="","Blank",IFERROR(IF(AND(LEN(TRIM(J7))=10,VALUE(TRIM(J7))>0),"Valid","Invalid"),"Invalid"))
A8: M00007 | B8: C0002 | C8: V01 | D8: Thigul narsapur | E8: Environment | F8: M.Laxminarsimhareddy | G8: Male | H8: President | I8: President | J8: 9652472270 | K8: =IF(TRIM(J8&"")="","Blank",IFERROR(IF(AND(LEN(TRIM(J8))=10,VALUE(TRIM(J8))>0),"Valid","Invalid"),"Invalid"))
A9: M00008 | B9: C0002 | C9: V01 | D9: Thigul narsapur | E9: Environment | F9: M.Manasa | G9: Female | H9: Vice President | I9: Wise President | J9: 8019236164 | K9: =IF(TRIM(J9&"")="","Blank",IFERROR(IF(AND(LEN(TRIM(J9))=10,VALUE(TRIM(J9))>0),"Valid","Invalid"),"Invalid"))
A10: M00009 | B10: C0002 | C10: V01 | D10: Thigul narsapur | E10: Environment | F10: M.Mamatha | G10: Female | H10: Secretary | I10: Setcetory | J10: 8008737257 | K10: =IF(TRIM(J10&"")="","Blank",IFERROR(IF(AND(LEN(TRIM(J10))=10,VALUE(TRIM(J10))>0),"Valid","Invalid"),"Invalid"))
A11: M00010 | B11: C0002 | C11: V01 | D11: Thigul narsapur | E11: Environment | F11: A.Ramulu chari | G11: Male | H11: Member | I11: Member | J11: 96525923 | K11: =IF(TRIM(J11&"")="","Blank",IFERROR(IF(AND(LEN(TRIM(J11))=10,VALUE(TRIM(J11))>0),"Valid","Invalid"),"Invalid"))
A12: M00011 | B12: C0002 | C12: V01 | D12: Thigul narsapur | E12: Environment | F12: Kancharla Mahipal | G12: Male | H12: Member | I12: Member | J12: 8106392629 | K12: =IF(TRIM(J12&"")="","Blank",IFERROR(IF(AND(LEN(TRIM(J12))=10,VALUE(TRIM(J12))>0),"Valid","Invalid"),"Invalid"))
A13: M00012 | B13: C0003 | C13: V01 | D13: Thigul narsapur | E13: Education | F13: U.Narsimhulu | G13: Male | H13: President | I13: President | J13: 9676218478 | K13: =IF(TRIM(J13&"")="","Blank",IFERROR(IF(AND(LEN(TRIM(J13))=10,VALUE(TRIM(J13))>0),"Valid","Invalid"),"Invalid"))
... A27: M00026 | B27: C0005 | C27: V01 | D27: Thigul narsapur | E27: Water | F27: Kancharla Shoba | G27: Female | H27: Secretary | I27: Secretory | J27: 9550035473 | K27: =IF(TRIM(J27&"")="","Blank",IFERROR(IF(AND(LEN(TRIM(J27))=10,VALUE(TRIM(J27))>0),"Valid","Invalid"),"Invalid"))
A28: M00027 | B28: C0005 | C28: V01 | D28: Thigul narsapur | E28: Water | F28: eluri narsimhulu | G28: Male | H28: Member | I28: member | K28: =IF(TRIM(J28&"")="","Blank",IFERROR(IF(AND(LEN(TRIM(J28))=10,VALUE(TRIM(J28))>0),"Valid","Invalid"),"Invalid"))
A29: M00028 | B29: C0005 | C29: V01 | D29: Thigul narsapur | E29: Water | F29: Melugu Bhagyamma | G29: Female | H29: Member | I29: member | J29: 9390667661 | K29: =IF(TRIM(J29&"")="","Blank",IFERROR(IF(AND(LEN(TRIM(J29))=10,VALUE(TRIM(J29))>0),"Valid","Invalid"),"Invalid"))
A30: M00029 | B30: C0006 | C30: V01 | D30: Thigul narsapur | E30: Health | F30: M.Kavitha | G30: Female | H30: President | I30: President | J30: 7893213229 | K30: =IF(TRIM(J30&"")="","Blank",IFERROR(IF(AND(LEN(TRIM(J30))=10,VALUE(TRIM(J30))>0),"Valid","Invalid"),"Invalid"))
A31: M00030 | B31: C0006 | C31: V01 | D31: Thigul narsapur | E31: Health | F31: M.Ravinder | G31: Male | H31: Vice President | I31: Wise President | K31: =IF(TRIM(J31&"")="","Blank",IFERROR(IF(AND(LEN(TRIM(J31))=10,VALUE(TRIM(J31))>0),"Valid","Invalid"),"Invalid"))
A32: M00031 | B32: C0006 | C32: V01 | D32: Thigul narsapur | E32: Health | F32: MD Sulthana Begum | G32: Female | H32: Secretary | I32: Secretory | J32: 9550940295 | K32: =IF(TRIM(J32&"")="","Blank",IFERROR(IF(AND(LEN(TRIM(J32))=10,VALUE(TRIM(J32))>0),"Valid","Invalid"),"Invalid"))
A33: M00032 | B33: C0006 | C33: V01 | D33: Thigul narsapur | E33: Health | F33: M.Anitha | G33: Female | H33: Member | I33: Member | K33: =IF(TRIM(J33&"")="","Blank",IFERROR(IF(AND(LEN(TRIM(J33))=10,VALUE(TRIM(J33))>0),"Valid","Invalid"),"Invalid"))
A34: M00033 | B34: C0006 | C34: V01 | D34: Thigul narsapur | E34: Health | F34: P.Devendra | G34: Female | H34: Member | I34: Member | J34: 9652592370 | K34: =IF(TRIM(J34&"")="","Blank",IFERROR(IF(AND(LEN(TRIM(J34))=10,VALUE(TRIM(J34))>0),"Valid","Invalid"),"Invalid"))
A35: M00034 | B35: C0007 | C35: V01 | D35: Thigul narsapur | E35: Farmer | F35: M.Narsimhulu | G35: Male | H35: President | I35: President | J35: 7702501584 | K35: =IF(TRIM(J35&"")="","Blank",IFERROR(IF(AND(LEN(TRIM(J35))=10,VALUE(TRIM(J35))>0),"Valid","Invalid"),"Invalid"))
A36: M00035 | B36: C0007 | C36: V01 | D36: Thigul narsapur | E36: Farmer | F36: K.Venkatreddi | G36: Male | H36: Vice President | I36: Wise Presidend | J36: 9908976945 | K36: =IF(TRIM(J36&"")="","Blank",IFERROR(IF(AND(LEN(TRIM(J36))=10,VALUE(TRIM(J36))>0),"Valid","Invalid"),"Invalid"))
A37: M00036 | B37: C0007 | C37: V01 | D37: Thigul narsapur | E37: Farmer | F37: G.Yadamma | G37: Female | H37: Member | I37: Member | K37: =IF(TRIM(J37&"")="","Blank",IFERROR(IF(AND(LEN(TRIM(J37))=10,VALUE(TRIM(J37))>0),"Valid","Invalid"),"Invalid"))
A38: M00037 | B38: C0007 | C38: V01 | D38: Thigul narsapur | E38: Farmer | F38: Ch.Bhagyalaxmi | G38: Female | H38: Member | I38: Member | J38: 9666601990 | K38: =IF(TRIM(J38&"")="","Blank",IFERROR(IF(AND(LEN(TRIM(J38))=10,VALUE(TRIM(J38))>0),"Valid","Invalid"),"Invalid"))
A39: M00038 | B39: C0007 | C39: V01 | D39: Thigul narsapur | E39: Farmer | F39: K.Manjula | G39: Female | H39: Member | K39: =IF(TRIM(J39&"")="","Blank",IFERROR(IF(AND(LEN(TRIM(J39))=10,VALUE(TRIM(J39))>0),"Valid","Invalid"),"Invalid"))
A40: M00039 | B40: C0008 | C40: V02 | D40: B.G.Venkatapur | E40: Environment | F40: Neela Manjula | G40: Female | H40: President | I40: President | J40: 9866537242 | K40: =IF(TRIM(J40&"")="","Blank",IFERROR(IF(AND(LEN(TRIM(J40))=10,VALUE(TRIM(J40))>0),"Valid","Invalid"),"Invalid"))
A41: M00040 | B41: C0008 | C41: V02 | D41: B.G.Venkatapur | E41: Environment | F41: Bheedu Shankar | G41: Male | H41: Vice President | I41: Wise President | J41: 9963439257 | K41: =IF(TRIM(J41&"")="","Blank",IFERROR(IF(AND(LEN(TRIM(J41))=10,VALUE(TRIM(J41))>0),"Valid","Invalid"),"Invalid"))
A42: M00041 | B42: C0008 | C42: V02 | D42: B.G.Venkatapur | E42: Environment | F42: Thumma Kanakaiah | G42: Male | H42: Secretary | I42: Secretory | J42: 9550289847 | K42: =IF(TRIM(J42&"")="","Blank",IFERROR(IF(AND(LEN(TRIM(J42))=10,VALUE(TRIM(J42))>0),"Valid","Invalid"),"Invalid"))
A43: M00042 | B43: C0008 | C43: V02 | D43: B.G.Venkatapur | E43: Environment | F43: Gundamaina Kanakamma | G43: Female | H43: Member | I43: Member | J43: 9989743967 | K43: =IF(TRIM(J43&"")="","Blank",IFERROR(IF(AND(LEN(TRIM(J43))=10,VALUE(TRIM(J43))>0),"Valid","Invalid"),"Invalid"))
A44: M00043 | B44: C0008 | C44: V02 | D44: B.G.Venkatapur | E44: Environment | F44: Nagapuri Padma | G44: Female | H44: Member | I44: Member | J44: 8790188135 | K44: =IF(TRIM(J44&"")="","Blank",IFERROR(IF(AND(LEN(TRIM(J44))=10,VALUE(TRIM(J44))>0),"Valid","Invalid"),"Invalid"))
A45: M00044 | B45: C0008 | C45: V02 | D45: B.G.Venkatapur | E45: Environment | F45: Ramidla Navaveetha | G45: Female | H45: Member | I45: Member | J45: 9553393452 | K45: =IF(TRIM(J45&"")="","Blank",IFERROR(IF(AND(LEN(TRIM(J45))=10,VALUE(TRIM(J45))>0),"Valid","Invalid"),"Invalid"))
A46: M00045 | B46: C0009 | C46: V02 | D46: B.G.Venkatapur | E46: Farmer | F46: Ch.Narsinhulu | G46: Male | H46: President | I46: President | J46: 9676234141 | K46: =IF(TRIM(J46&"")="","Blank",IFERROR(IF(AND(LEN(TRIM(J46))=10,VALUE(TRIM(J46))>0),"Valid","Invalid"),"Invalid"))
A47: M00046 | B47: C0009 | C47: V02 | D47: B.G.Venkatapur | E47: Farmer | F47: N.Sathyanarayana | G47: Male | H47: Vice President | I47: Wise President | J47: 9908770118 | K47: =IF(TRIM(J47&"")="","Blank",IFERROR(IF(AND(LEN(TRIM(J47))=10,VALUE(TRIM(J47))>0),"Valid","Invalid"),"Invalid"))
A48: M00047 | B48: C0009 | C48: V02 | D48: B.G.Venkatapur | E48: Farmer | F48: P.Babu | G48: Male | H48: Secretary | I48: Secretory | J48: 9666072565 | K48: =IF(TRIM(J48&"")="","Blank",IFERROR(IF(AND(LEN(TRIM(J48))=10,VALUE(TRIM(J48))>0),"Valid","Invalid"),"Invalid"))
A49: M00048 | B49: C0009 | C49: V02 | D49: B.G.Venkatapur | E49: Farmer | F49: N.Srikanth | G49: Male | H49: Member | I49: member | J49: 9666223530 | K49: =IF(TRIM(J49&"")="","Blank",IFERROR(IF(AND(LEN(TRIM(J49))=10,VALUE(TRIM(J49))>0),"Valid","Invalid"),"Invalid"))
A50: M00049 | B50: C0009 | C50: V02 | D50: B.G.Venkatapur | E50: Farmer | F50: B.Mallesham | G50: Male | H50: Member | I50: member | J50: 9866569160 | K50: =IF(TRIM(J50&"")="","Blank",IFERROR(IF(AND(LEN(TRIM(J50))=10,VALUE(TRIM(J50))>0),"Valid","Invalid"),"Invalid"))
A51: M00050 | B51: C0009 | C51: V02 | D51: B.G.Venkatapur | E51: Farmer | F51: Ch.Narsamma | G51: Female | H51: Member | I51: member | K51: =IF(TRIM(J51&"")="","Blank",IFERROR(IF(AND(LEN(TRIM(J51))=10,VALUE(TRIM(J51))>0),"Valid","Invalid"),"Invalid"))
A52: M00051 | B52: C0009 | C52: V02 | D52: B.G.Venkatapur | E52: Farmer | F52: Ch.Andalu | G52: Female | H52: Member | I52: member | K52: =IF(TRIM(J52&"")="","Blank",IFERROR(IF(AND(LEN(TRIM(J52))=10,VALUE(TRIM(J52))>0),"Valid","Invalid"),"Invalid"))
A53: M00052 | B53: C0009 | C53: V02 | D53: B.G.Venkatapur | E53: Farmer | F53: T.Balanarsamma | G53: Female | H53: Member | I53: member | K53: =IF(TRIM(J53&"")="","Blank",IFERROR(IF(AND(LEN(TRIM(J53))=10,VALUE(TRIM(J53))>0),"Valid","Invalid"),"Invalid"))
...

Sheet Action_Plans
A1: Plan_ID | B1: Village_ID | C1: Village | D1: Committee_ID | E1: Committee_Name | F1: DA_ID | G1: Type | H1: Frequency | I1: Assigned_Date | J1: Notes
A2: P0001 | B2: V01 | C2: Thigul narsapur | D2: C0001 | E2: VDC | F2: =INDEX(Villages!F:F,MATCH(B2,Villages!A:A,0))
A3: P0002 | B3: V01 | C3: Thigul narsapur | D3: C0002 | E3: Environment | F3: =INDEX(Villages!F:F,MATCH(B3,Villages!A:A,0))
A4: P0003 | B4: V01 | C4: Thigul narsapur | D4: C0003 | E4: Education | F4: =INDEX(Villages!F:F,MATCH(B4,Villages!A:A,0))
A5: P0004 | B5: V01 | C5: Thigul narsapur | D5: C0004 | E5: Technical & Youth | F5: =INDEX(Villages!F:F,MATCH(B5,Villages!A:A,0))
A6: P0005 | B6: V01 | C6: Thigul narsapur | D6: C0005 | E6: Water | F6: =INDEX(Villages!F:F,MATCH(B6,Villages!A:A,0))
A7: P0006 | B7: V01 | C7: Thigul narsapur | D7: C0006 | E7: Health | F7: =INDEX(Villages!F:F,MATCH(B7,Villages!A:A,0))
A8: P0007 | B8: V01 | C8: Thigul narsapur | D8: C0007 | E8: Farmer | F8: =INDEX(Villages!F:F,MATCH(B8,Villages!A:A,0))
A9: P0008 | B9: V02 | C9: B.G.Venkatapur | D9: C0008 | E9: Environment | F9: =INDEX(Villages!F:F,MATCH(B9,Villages!A:A,0))
A10: P0009 | B10: V02 | C10: B.G.Venkatapur | D10: C0009 | E10: Farmer | F10: =INDEX(Villages!F:F,MATCH(B10,Villages!A:A,0))
A11: P0010 | B11: V02 | C11: B.G.Venkatapur | D11: C0010 | E11: Gender | F11: =INDEX(Villages!F:F,MATCH(B11,Villages!A:A,0))
A12: P0011 | B12: V02 | C12: B.G.Venkatapur | D12: C0011 | E12: Health | F12: =INDEX(Villages!F:F,MATCH(B12,Villages!A:A,0))
A13: P0012 | B13: V02 | C13: B.G.Venkatapur | D13: C0012 | E13: Problem Solving | F13: =INDEX(Villages!F:F,MATCH(B13,Villages!A:A,0))
... A352: P0351 | B352: V42 | C352: Ontimamidipalli | D352: C0351 | E352: Gender | F352: =INDEX(Villages!F:F,MATCH(B352,Villages!A:A,0))

Sheet Attendance_Entries
A1: Entry_ID | B1: Plan_ID | C1: DA_ID | D1: DA_Name | E1: Village | F1: Committee_Name | G1: Entry_Date | H1: Status | I1: Reason | J1: Image_URL | K1: Male_Count_Live | L1: Female_Count_Live | M1: Total_Count_Live | N1: Male_Total_Master | O1: Female_Total_Master | P1: New_Members_Count | Q1: Visit_Designations | R1: GPS_Lat | S1: GPS_Long

Sheet Specials_Entries
A1: Entry_ID | B1: Plan_ID | C1: DA_ID | D1: DA_Name | E1: Village | F1: Committee_Name | G1: Special | H1: Entry_Date | I1: Status | J1: Reason | K1: Image_URL | L1: Participants_Count | M1: Scope | N1: GPS_Lat | O1: GPS_Long

Sheet PMs
A1: PM_ID | B1: PM_Name | C1: Access_Scope | D1: Email | E1: Mobile
A2: PM01 | B2: Ravi Teja Naidu (TEMP) | C2: All Clusters
A3: PM02 | B3: Lakshmi Priya Rao (TEMP) | C3: All Clusters

Sheet PCs
A1: PC_ID | B1: PC_Name | C1: Cluster | D1: Email | E1: Mobile
A2: PC01 | B2: CSRB | C2: CSRB
A3: PC02 | B3: PDTC | C3: PDTC

Sheet PC_DA_Map
A1: Map_ID | B1: PC_ID | C1: DA_ID | D1: DA_Name | E1: Cluster
A2: M001 | B2: PC01 | C2: D01 | D2: D.Ramesh | E2: CSRB
A3: M002 | B3: PC01 | C3: D02 | D3: K.Krishna | E3: CSRB
A4: M003 | B4: PC02 | C4: D03 | D4: K.Vinaykumar | E4: PDTC
A5: M004 | B5: PC01 | C5: D04 | D5: M.Venkatesh | E5: CSRB
A6: M005 | B6: PC02 | C6: D05 | D6: P.Shankar | E6: PDTC
A7: M006 | B7: PC02 | C7: D06 | D7: R.Vinay | E7: PDTC
A8: M007 | B8: PC01 | C8: D07 | D8: T.Ramesh | E8: CSRB
A9: M008 | B9: PC01 | C9: D08 | D9: V.Ramesh | E9: CSRB
A10: M009 | B10: PC02 | C10: D09 | D10: Y.Rakesh | E10: PDTC

Sheet RBAC_Permissions
A1: Role | B1: Data Scope | C1: View | D1: Add | E1: Edit | F1: Move | G1: Enable/Disable | H1: Delete | I1: Restore (Bin)
A2: Admin | B2: Everything (all Clusters, PMs, PCs, DAs, Villages, Committees, Plans, Entries) | C2: Yes | D2: Yes | E2: Yes | F2: Yes | G2: Yes | H2: Yes | I2: Yes
A3: PM | B3: All PCs + all DAs + all Villages, org-wide (PMs have no Cluster of their own) | C3: Yes | D3: No | E3: No | F3: No | G3: No | H3: No | I3: No
A4: PC | B4: Own DAs only (via PC_DA_Map) + those DAs' Villages, Action Plans, submissions | C4: Yes | D4: Action Plans only | E4: Action Plans only | F4: No | G4: No | H4: No | I4: No
A5: DA | B5: Own Villages only (via Villages.DA_ID) + own Attendance/Specials entries | C5: Own data only | D5: Own entries only | E5: Own entries only | F5: No | G5: No | H5: No | I5: No
A7: Recycle Bin rule (Admin only): Delete = soft-delete -> moves record to Recycle_Bin sheet. Auto-purge after 10 days (Auto_Purge_Date = Deleted_At + 10). Restore before purge re-inserts the record into its source sheet.
A8: PC-sees-other-PC-data: not implemented at PC level (each PC still sees only its own DAs via PC_DA_Map). PM sits above every PC with no Cluster restriction and consolidates the cross-PC view. Flag if PCs should also see each other's data directly.

Sheet Recycle_Bin
A1: Bin_ID | B1: Source_Sheet | C1: Record_ID | D1: Record_Summary | E1: Deleted_By | F1: Deleted_At | G1: Auto_Purge_Date | H1: Status
